Workbook

Sheet 3 Frameworks Combined
A1: SCF Domain | B1: SCF Control | D1: SCF # | E1: Secure Controls Framework (SCF) Control Description | F1: Evidence Request List (ERL) # | G1: Possible Solutions & Considerations Enterprise (> 1,000 staff) BLS Firm Size Class 9 | H1: SCF Control Question | I1: Relative Control Weighting | J1: PPTDF Applicability PEOPLE | K1: PPTDF Applicability PROCESS | L1: PPTDF Applicability TECHNOLOGY | M1: PPTDF Applicability DATA | N1: PPTDF Applicability FACILITY | O1: NIST CSF Function Grouping | P1: SCRM Focus TIER 1 STRATEGIC | Q1: SCRM Focus TIER 2 OPERATIONAL | R1: SCRM Focus TIER 3 TACTICAL | S1: C|P-CMM 0 Not Performed | T1: C|P-CMM 1 Performed Informally | U1: C|P-CMM 2 Planned & Tracked+AI:AL | V1: C|P-CMM 3 Well Defined | W1: C|P-CMM 4 Quantitatively Controlled | X1: C|P-CMM 5 Continuously Improving | Y1: CIS CSC v8.1 | Z1: NIST CSF v2.0 | AA1: PCI DSS v4.0.1 | AB1: US SOX | AC1: Risk Threat Summary | AD1: Risk R-AC-1 | AE1: Risk R-AC-2 | AF1: Risk R-AC-3 | AG1: Risk R-AC-4 | AH1: Risk R-AM-1 | AI1: Risk R-AM-2 | AJ1: Risk R-AM-3 | AK1: Risk R-BC-1 | AL1: Risk R-BC-2 | AM1: Risk R-BC-3 | AN1: Risk R-BC-4 | AO1: Risk R-BC-5 | AP1: Risk R-EX-1 | AQ1: Risk R-EX-2 | AR1: Risk R-EX-3 | AS1: Risk R-EX-4 | AT1: Risk R-EX-5 | AU1: Risk R-EX-6 | AV1: Risk R-EX-7 | AW1: Risk R-GV-1 | AX1: Risk R-GV-2 | AY1: Risk R-GV-3 | AZ1: Risk R-GV-4 | BA1: Risk R-GV-5 | BB1: Risk R-GV-6 | BC1: Risk R-GV-7 | BD1: Risk R-GV-8 | BE1: Risk R-IR-1 | BF1: Risk R-IR-2 | BG1: Risk R-IR-3 | BH1: Risk R-IR-4 | BI1: Risk R-SA-1 | BJ1: Risk R-SA-2 | BK1: Risk R-SC-1 | BL1: Risk R-SC-2 | BM1: Risk R-SC-3 | BN1: Risk R-SC-4 | BO1: Risk R-SC-5 | BP1: Risk R-SC-6 | BQ1: Control Threat Summary | BR1: Threat NT-1 | BS1: Threat NT-2 | BT1: Threat NT-3 | BU1: Threat NT-4 | BV1: Threat NT-5 | BW1: Threat NT-6 | BX1: Threat NT-7 | BY1: Threat NT-8 | BZ1: Threat NT-9 | CA1: Threat NT-10 | CB1: Threat NT-11 | CC1: Threat NT-12 | CD1: Threat NT-13 | CE1: Threat NT-14 | CF1: Threat MT-1 | CG1: Threat MT-2 | CH1: Threat MT-3 | CI1: Threat MT-4 | CJ1: Threat MT-5 | CK1: Threat MT-6 | CL1: Threat MT-7 | CM1: Threat MT-8 | CN1: Threat MT-9 | CO1: Threat MT-10 | CP1: Threat MT-11 | CQ1: Threat MT-12 | CR1: Threat MT-13 | CS1: Threat MT-14 | CT1: Threat MT-15 | CU1: Threat MT-16 | CV1: Threat MT-17 | CW1: Threat MT-18 | CX1: Threat MT-19 | CY1: Threat MT-20 | CZ1: Threat MT-21 | DA1: Threat MT-22 | DB1: Threat MT-23
A2: Asset Management | B2: Asset Inventories | C2: =VLOOKUP(D2,'Threat Model'!$P$2:$Q$96,1,FALSE) -> #N/A | D2: AST-02 | E2: Mechanisms exist to perform inventories of technology assets that: (1) Accurately reflects the current systems, applications and services in use; (2) Identifies authorized software products, including business justification details; (3) Is at the level of granularity deemed necessary for tracking and reporting; (4) Includes organization-defined information deemed necessary to achieve effective property accountability; and (5) Is available for review and audit by designated organizational personnel. | F2: E-AST-04 E-AST-05 E-AST-07 | G2: ∙ IT Asset Management (ITAM) program ∙ Configuration Management Database (CMDB) ∙ ManageEngine AssetExplorer (https://manageengine.com) ∙ Ivanti (https://ivanti.com) ∙ ServiceNow (https://servicenow.com) ∙ Solarwinds (https://solarwinds.com) ∙ JAMF (https://jamf.com) | H2: Does the organization perform inventories of technology assets that: (1) Accurately reflects the current systems, applications and services in use; (2) Identifies authorized software products, including business justification details; (3) Is at the level of granularity deemed necessary for tracking and reporting; (4) Includes organization-defined information deemed necessary to achieve effective property accountability; and (5) Is available for review and audit by designated organizational personnel? | I2: 10 | K2: x | O2: Identify | Q2: x | R2: x | S2: There is no evidence of a capability to perform inventories of technology assets that: (1) Accurately reflects the current systems, applications and services in use; (2) Identifies authorized software products, including business justification details; (3) Is at the level of granularity deemed necessary for tracking and reporting; (4) Includes organization-defined information deemed necessary to achieve effective property accountability; and (5) Is available for review and audit by designated organizational personnel. | T2: Asset Management (AST) efforts are ad hoc and inconsistent. CMM Level 1 control maturity would reasonably expect all, or at least most, the following criteria to exist: • Asset management is informally assigned as an additional duty to existing IT/cybersecurity personnel. • Asset inventories are performed in an ad hoc manner. • Software licensing is tracked as part of IT asset inventories. • Data process owners maintain limited network diagrams to document the flow of sensitive/regulated data that is specific to their initiative. • IT personnel work with data/process owners to help ensure secure practices are implemented throughout the System Development Lifecycle (SDLC) for all high-value projects. • Inventories are manual (e.g., spreadsheets). • Assets are assigned owners and are documented. • No structured process exists to review or share the results of the inventories. | U2: Asset Management (AST) efforts are requirements-driven and governed at a local/regional level, but are not consistent across the organization. CMM Level 2 control maturity would reasonably expect all, or at least most, the following criteria to exist: • Asset management is decentralized (e.g., a localized/regionalized function) and uses non-standardized methods to implement secure, resilient and compliant practices. • IT/cybersecurity personnel identify cybersecurity & data protection controls that are appropriate to address applicable statutory, regulatory and contractual requirements for asset management. • Administrative processes and technologies focus on protecting High Value Assets (HVAs), including environments where sensitive/regulated data is stored, transmitted and processed. • Asset management is formally assigned as an additional duty to existing IT/cybersecurity personnel. • Technology assets are categorized according to data classification and business criticality. • Inventories cover technology assets in scope for statutory, regulatory and/ or contractual compliance, which includes both physical and virtual assets. • Software licensing is tracked as part of IT asset inventories. • Users are educated on their responsibilities to protect technology assets assigned to them or under their supervision. • IT/cybersecurity personnel maintain network diagrams to document the flow of sensitive/regulated data across the network. • Maintenance of asset inventory is performed at least annually. • Inventory of physical technology assets are assigned to individual users or teams and covers common devices (e.g., laptops, workstations and servers). • Inventories may be manual (e.g., spreadsheets) or automated. • No structured process exists to review or share the results of the inventories. • Annual IT asset inventories validate or update stakeholders /owners. | V2: Asset Management (AST) efforts are standardized across the organization and centrally managed, where technically feasible, to ensure consistency. CMM Level 3 control maturity would reasonably expect all, or at least most, the following criteria to exist: • An IT Asset Management (ITAM) function, or similar function, governs asset management to help ensure compliance with requirements for asset management. • An ITAM function, or similar function, maintains an inventory of IT assets, covering both physical and virtual assets, as well as centrally managed asset ownership assignments. • Technology assets and data are categorized according to data classification and business criticality criteria. • A Cybersecurity Supply Chain Risk Management (C-SCRM) function oversees supply chain risks including the removal and prevention of certain technology services and/ or equipment designated as supply chain threats by a statutory or regulatory body. • Data/process owners document where sensitive/regulated data is stored, transmitted and processed, generating Data Flow Diagrams (DFDs) and network diagrams to document the flow of data. • Quarterly IT asset inventories are reviewed and shared with appropriate stakeholders. • Inventories are predominately automated, but may have some manual components (e.g., cloud-based assets that are out of scope for automated inventory scans). • Inventories processes include Indicators of Compromise (IoC) to identify evidence of physical tampering. • Inventory scans are configured to be recurring, based on ITAM tool configuration settings. • Annual IT asset inventories validate or update stakeholders / owners. • A Software Asset Management (SAM) solution is used to centrally manage deployed software. • An ITAM function, or similar function, conducts ongoing “technical debt” reviews of hardware and software technologies to remediate outdated and/ or unsupported technologies. | W2: Asset Management (AST) efforts are metrics driven and provide sufficient management insight (based on a quantitative understanding of process capabilities) to predict optimal performance, ensure continued operations and identify areas for improvement. • Metrics reporting includes quantitative analysis of Key Performance Indicators (KPIs). • Metrics reporting includes quantitative analysis of Key Risk Indicators (KRIs). • Scope of metrics, KPIs and KRIs covers organization-wide cybersecurity & data protection controls, including functions performed by third-parties. • Organizational leadership maintains a formal process to objectively review and respond to metrics, KPIs and KRIs (e.g., monthly or quarterly review). • Based on metrics analysis, process improvement recommendations are submitted for review and are handled in accordance with change control processes. • Both business and technical stakeholders are involved in reviewing and approving proposed changes. | X2: Asset Management (AST) efforts are “world-class” capabilities that leverage predictive analysis (e.g., machine learning, AI, etc.). In addition to CMM Level 4 criteria, CMM Level 5 control maturity would reasonably expect all, or at least most, the following criteria to exist: • Stakeholders make time-sensitive decisions to support operational efficiency, which may include automated remediation actions. • Based on predictive analysis, process improvements are implemented according to “continuous improvement” practices that affect process changes. | Y2: 1 1.1 2 2.1 2.2 2.4 6.6 | Z2: ID.AM ID.AM-01 ID.AM-02 | AA2: 6.3.2 9.5.1 9.5.1.1 11.2 11.2.2 | AC2: R-AC-2 R-AC-3 R-AC-4 R-AM-2 R-AM-3 R-BC-1 R-BC-2 R-BC-3 R-BC-4 R-EX-6 R-GV-1 R-GV-2 R-GV-4 R-GV-5 R-GV-6 R-GV-7 R-IR-1 R-IR-3 R-SC-1 R-SC-2 R-SC-3 R-SC-4 R-SC-5 R-SC-6 | AE2: R-AC-2 | AF2: R-AC-3 | AG2: R-AC-4 | AI2: R-AM-2 | AJ2: R-AM-3 | AK2: R-BC-1 | AL2: R-BC-2 | AM2: R-BC-3 | AN2: R-BC-4 | AU2: R-EX-6 | AW2: R-GV-1 | AX2: R-GV-2 | AZ2: R-GV-4 | BA2: R-GV-5 | BB2: R-GV-6 | BC2: R-GV-7 | BE2: R-IR-1 | BG2: R-IR-3 | BK2: R-SC-1 | BL2: R-SC-2 | BM2: R-SC-3 | BN2: R-SC-4 | BO2: R-SC-5 | BP2: R-SC-6 | BQ2: =_xlfn.TEXTJOIN(CHAR(10),TRUE,BR2:DB2) -> NT-2 NT-3 NT-4 NT-5 NT-6 NT-7 NT-8 NT-9 NT-10 NT-11 NT-12 NT-13 NT-14 MT-1 MT-2 MT-3 MT-4 MT-5 MT-6 MT-7 MT-8 MT-9 MT-10 MT-11 MT-12 MT-13 MT-14 MT-15 | BS2: NT-2 | BT2: NT-3 | BU2: NT-4 | BV2: NT-5 | BW2: NT-6 | BX2: NT-7 | BY2: NT-8 | BZ2: NT-9 | CA2: NT-10 | CB2: NT-11 | CC2: NT-12 | CD2: NT-13 | CE2: NT-14 | CF2: MT-1 | CG2: MT-2 | CH2: MT-3 | CI2: MT-4 | CJ2: MT-5 | CK2: MT-6 | CL2: MT-7 | CM2: MT-8 | CN2: MT-9 | CO2: MT-10 | CP2: MT-11 | CQ2: MT-12 | CR2: MT-13 | CS2: MT-14 | CT2: MT-15
A3: Identification & Authentication | B3: Privileged Account Inventories | C3: =VLOOKUP(D3,'Threat Model'!$P$2:$Q$96,1,FALSE) -> #N/A | D3: IAC-16.1 | E3: Mechanisms exist to inventory all privileged accounts and validate that each person with elevated privileges is authorized by the appropriate level of organizational management. | F3: E-IAM-03 | G3: ∙ Microsoft Active Directory (https://microsoft.com) ∙ Microsoft Entra (https://microsoft.com) ∙ AWS IAM (https://aws.amazon.com) | H3: Does the organization inventory all privileged accounts and validate that each person with elevated privileges is authorized by the appropriate level of organizational management? | I3: 10 | L3: x | O3: Protect | R3: x | S3: There is no evidence of a capability to inventory all privileged accounts and validate that each pers on with elevated privileges is authorized by the appropriate level of organizational management. | T3: Identification & Authentication (IAC) efforts are ad hoc and inconsistent. CMM Level 1 control maturity would reasonably expect all, or at least most, the following criteria to exist: • Identity & Access Management (IAM) is decentralized where Active Directory (AD), or a similar technology, may be used to centrally manage identities and permissions, but asset/process owners are authorized to operate a decentralized access control program for their specific systems, applications and services. • IAM controls are primarily administrative in nature (e.g., policies & standards) to manage accounts and permissions. • IT personnel identify and implement IAM cybersecurity & data protection controls that are appropriate to address applicable statutory, regulatory and contractual requirements. | U3: Identification & Authentication (IAC) efforts are requirements-driven and governed at a local/regional level, but are not consistent across the organization. CMM Level 2 control maturity would reasonably expect all, or at least most, the following criteria to exist: • Logical Access Control (LAC) is decentralized (e.g., a localized/regionalized function) and uses non-standardized methods to implement secure, resilient and compliant practices. • IT/cybersecurity personnel identify cybersecurity & data protection controls that are appropriate to address applicable statutory, regulatory and contractual requirements for logical access control. • IT personnel: o Implement and maintain an Identity & Access Management (IAM) capability for all users to implement “least privileges” Role Based Access Control (RBAC) practices for the management of user, group and system accounts, including privileged accounts. o Govern IAM technologies via RBAC to prohibit privileged access by non-organizational users, unless there is an explicit support contract for privileged IT support services. • Active Directory (AD), or a similar technology, is primarily used to centrally manage identities and permissions with RBAC. Due to technical or business limitations, asset/process owners are empowered to operate a decentralized access control program for their specific systems, applications and services that cannot be integrated into AD. • IAM controls are primarily administrative in nature (e.g., policies & standards) to manage accounts and permissions. • Administrative processes and technologies inventory all privileged accounts and validate that each pers on with elevated privileges is authorized by the appropriate level of organizational management. | V3: Identification & Authentication (IAC) efforts are standardized across the organization and centrally managed, where technically feasible, to ensure consistency. CMM Level 3 control maturity would reasonably expect all, or at least most, the following criteria to exist: • An Identity & Access Management (IAM) function, or similar function, centrally manages permissions and implements “least privileges” Role Based Access Control (RBAC) practices for the management of user, group and system accounts, including privileged accounts. • The Human Resources (HR) department governs personnel management operations and notifies IAM personnel of personnel role changes for RBAC-based provisioning and deprovisioning actions. • An IT Asset Management (ITAM) function, or similar function, categorizes endpoint devices according to the data the asset stores, transmits and/ or processes and applies the appropriate technology controls to protect the asset and data that conform to industry-recognized standards for hardening (e.g., DISA STIGs, CIS Benchmarks or OEM security guides). • An IT infrastructure team, or similar function, ensures that statutory, regulatory and contractual cybersecurity & data privacy obligations are addressed to ensure secure configurations are designed, built and maintained. • Active Directory (AD), or a similar technology, is used to centrally manage identities and permissions. Only by exception due to a technical or business limitation are solutions authorized to operate a decentralized access control program for systems, applications and services. • Administrative processes and technologies inventory all privileged accounts and validate that each pers on with elevated privileges is authorized by the appropriate level of organizational management. | W3: Identification & Authentication (IAC) efforts are metrics driven and provide sufficient management insight (based on a quantitative understanding of process capabilities) to predict optimal performance, ensure continued operations and identify areas for improvement. In addition to CMM Level 3 criteria, CMM Level 4 control maturity would reasonably expect all, or at least most, the following criteria to exist: • Metrics reporting includes quantitative analysis of Key Performance Indicators (KPIs). • Metrics reporting includes quantitative analysis of Key Risk Indicators (KRIs). • Scope of metrics, KPIs and KRIs covers organization-wide cybersecurity & data protection controls, including functions performed by third-parties. • Organizational leadership maintains a formal process to objectively review and respond to metrics, KPIs and KRIs (e.g., monthly or quarterly review). • Based on metrics analysis, process improvement recommendations are submitted for review and are handled in accordance with change control processes. • Both business and technical stakeholders are involved in reviewing and approving proposed changes. | X3: Identification & Authentication (IAC) efforts are “world-class” capabilities that leverage predictive analysis (e.g., machine learning, AI, etc.). In addition to CMM Level 4 criteria, CMM Level 5 control maturity would reasonably expect all, or at least most, the following criteria to exist: • Stakeholders make time-sensitive decisions to support operational efficiency, which may include automated remediation actions. • Based on predictive analysis, process improvements are implemented according to “continuous improvement” practices that affect process changes. | Y3: 5.1 5.5 | AA3: 7.2.4 | AC3: R-AC-1 R-AC-2 R-AC-3 R-AC-4 R-AM-1 R-AM-2 R-AM-3 R-BC-1 R-BC-2 R-BC-3 R-BC-4 R-EX-1 R-EX-2 R-EX-3 R-EX-4 R-EX-5 R-EX-6 R-EX-7 R-GV-1 R-GV-2 R-GV-3 R-GV-4 R-GV-5 R-GV-6 R-GV-7 R-GV-8 R-IR-1 R-IR-2 R-IR-3 R-IR-4 R-SA-1 R-SC-1 R-SC-2 R-SC-3 R-SC-4 R-SC-5 R-SC-6 | AD3: R-AC-1 | AE3: R-AC-2 | AF3: R-AC-3 | AG3: R-AC-4 | AH3: R-AM-1 | AI3: R-AM-2 | AJ3: R-AM-3 | AK3: R-BC-1 | AL3: R-BC-2 | AM3: R-BC-3 | AN3: R-BC-4 | AP3: R-EX-1 | AQ3: R-EX-2 | AR3: R-EX-3 | AS3: R-EX-4 | AT3: R-EX-5 | AU3: R-EX-6 | AV3: R-EX-7 | AW3: R-GV-1 | AX3: R-GV-2 | AY3: R-GV-3 | AZ3: R-GV-4 | BA3: R-GV-5 | BB3: R-GV-6 | BC3: R-GV-7 | BD3: R-GV-8 | BE3: R-IR-1 | BF3: R-IR-2 | BG3: R-IR-3 | BH3: R-IR-4 | BI3: R-SA-1 | BK3: R-SC-1 | BL3: R-SC-2 | BM3: R-SC-3 | BN3: R-SC-4 | BO3: R-SC-5 | BP3: R-SC-6 | BQ3: =_xlfn.TEXTJOIN(CHAR(10),TRUE,BR3:DB3) -> NT-7 MT-1 MT-2 MT-7 MT-8 MT-9 MT-10 MT-11 MT-12 MT-13 MT-14 MT-15 | BX3: NT-7 | CF3: MT-1 | CG3: MT-2 | CL3: MT-7 | CM3: MT-8 | CN3: MT-9 | CO3: MT-10 | CP3: MT-11 | CQ3: MT-12 | CR3: MT-13 | CS3: MT-14 | CT3: MT-15
A4: Continuous Monitoring | B4: Audit Trails | C4: =VLOOKUP(D4,'Threat Model'!$P$2:$Q$96,1,FALSE) -> #N/A | D4: MON-03.2 | E4: Mechanisms exist to link system access to individual users or service accounts. | G4: ∙ Secure Baseline Configurations (SBC) | H4: Does the organization link system access to individual users or service accounts? | I4: 10 | L4: x | O4: Detect | R4: x | S4: There is no evidence of a capability to link system access to individual users or service accounts. | T4: Continuous Monitoring (MON) efforts are ad hoc and inconsistent. CMM Level 1 control maturity would reasonably expect all, or at least most, the following criteria to exist: • Generating event logs and the review of event logs is narrowly-focused to business-critical systems and/ or systems that store, processes and/ or transmit sensitive/regulated data. • Secure baseline configurations generate logs that contain sufficient information to establish necessary details of activity and allow for forensics analysis. • Secure baseline configurations restrict access to event logs from privileged users to protect event logs and audit tools from unauthorized access, modification and deletion. | U4: Continuous Monitoring (MON) efforts are requirements-driven and governed at a local/regional level, but are not consistent across the organization. CMM Level 2 control maturity would reasonably expect all, or at least most, the following criteria to exist: • Situational awareness management is decentralized (e.g., a localized/regionalized function) and uses non-standardized methods to implement secure, resilient and compliant practices. • Secure baseline configurations generate logs that contain sufficient information to establish necessary details of activity and allow for forensics analysis. • IT/cybersecurity personnel: o Identify cybersecurity & data protection controls that are appropriate to address applicable statutory, regulatory and contractual requirements for situational awareness management. o Configure alerts for critical or sensitive data that is stored, transmitted and processed on assets. o Use a structured process to review and analyze logs. • A log aggregator, or similar automated tool, provides an event log report generation capability to aid in detecting and assessing anomalous activities on business-critical systems. | V4: Continuous Monitoring (MON) efforts are standardized across the organization and centrally managed, where technically feasible, to ensure consistency. CMM Level 3 control maturity would reasonably expect all, or at least most, the following criteria to exist: • An IT Asset Management (ITAM) function, or similar function: o Governs asset management that ensures compliance with requirements for asset management. o Leverages a Configuration Management Database (CMDB), or similar tool, as the authoritative source of IT assets. • A Security Incident Event Manager (SIEM), or similar automated tool: o Centrally collects logs and is protected according to the manufacturer’s security guidelines to protect the integrity of the event logs with cryptographic mechanisms. o Monitors the organization for Indicators of Compromise (IoC) and provides 24x7x365 near real-time alerting capability. o Is configured to alert incident response personnel of detected suspicious events such that incident responders can look to terminate suspicious events. • Both inbound and outbound network traffic is monitored for unauthorized activities to identify prohibited activities and assist incident handlers with identifying potentially compromised systems. | W4: See C|P-CMM3. There are no defined C|P-CMM4 criteria, since it is reasonable to assume a quantitatively-controlled process is not necessary to link system access to individual users or service accounts. | X4: See C|P-CMM4. There are no defined C|P-CMM5 criteria, since it is reasonable to assume a continuously-improving process is not necessary to link system access to individual users or service accounts. | AA4: 10.2 10.2.1 10.2.1.1 10.2.1.2 10.2.1.3 10.2.1.4 10.2.1.5 10.2.1.6 10.2.1.7 10.2.2 | AC4: R-AC-1 R-AC-2 R-AC-3 R-AC-4 R-AM-1 R-AM-2 R-AM-3 R-BC-1 R-BC-2 R-BC-3 R-BC-4 R-BC-5 R-EX-1 R-EX-2 R-EX-3 R-EX-4 R-EX-5 R-EX-6 R-EX-7 R-GV-1 R-GV-2 R-GV-3 R-GV-4 R-GV-5 R-GV-6 R-GV-7 R-GV-8 R-IR-1 R-IR-2 R-IR-3 R-IR-4 R-SA-1 R-SC-1 R-SC-2 R-SC-3 R-SC-4 R-SC-5 R-SC-6 | AD4: R-AC-1 | AE4: R-AC-2 | AF4: R-AC-3 | AG4: R-AC-4 | AH4: R-AM-1 | AI4: R-AM-2 | AJ4: R-AM-3 | AK4: R-BC-1 | AL4: R-BC-2 | AM4: R-BC-3 | AN4: R-BC-4 | AO4: R-BC-5 | AP4: R-EX-1 | AQ4: R-EX-2 | AR4: R-EX-3 | AS4: R-EX-4 | AT4: R-EX-5 | AU4: R-EX-6 | AV4: R-EX-7 | AW4: R-GV-1 | AX4: R-GV-2 | AY4: R-GV-3 | AZ4: R-GV-4 | BA4: R-GV-5 | BB4: R-GV-6 | BC4: R-GV-7 | BD4: R-GV-8 | BE4: R-IR-1 | BF4: R-IR-2 | BG4: R-IR-3 | BH4: R-IR-4 | BI4: R-SA-1 | BK4: R-SC-1 | BL4: R-SC-2 | BM4: R-SC-3 | BN4: R-SC-4 | BO4: R-SC-5 | BP4: R-SC-6 | BQ4: =_xlfn.TEXTJOIN(CHAR(10),TRUE,BR4:DB4) -> NT-7 MT-1 MT-2 MT-7 MT-8 MT-9 MT-10 MT-11 MT-12 MT-13 MT-14 MT-15 | BX4: NT-7 | CF4: MT-1 | CG4: MT-2 | CL4: MT-7 | CM4: MT-8 | CN4: MT-9 | CO4: MT-10 | CP4: MT-11 | CQ4: MT-12 | CR4: MT-13 | CS4: MT-14 | CT4: MT-15
A5: Identification & Authentication | B5: Periodic Review of Account Privileges | C5: =VLOOKUP(D5,'Threat Model'!$P$2:$Q$96,1,FALSE) -> #N/A | D5: IAC-17 | E5: Mechanisms exist to periodically-review the privileges assigned to individuals and service accounts to validate the need for such privileges and reassign or remove unnecessary privileges, as necessary. | F5: E-HRS-12 E-HRS-14 E-IAM-01 | H5: Does the organization periodically-review the privileges assigned to individuals and service accounts to validate the need for such privileges and reassign or remove unnecessary privileges, as necessary? | I5: 10 | K5: x | O5: Detect | Q5: x | R5: x | S5: There is no evidence of a capability to periodically-review the privileges assigned to individuals and service accounts to validate the need for such privileges and reassign or remove unnecessary privileges, as necessary. | T5: Identification & Authentication (IAC) efforts are ad hoc and inconsistent. CMM Level 1 control maturity would reasonably expect all, or at least most, the following criteria to exist: • Identity & Access Management (IAM) is decentralized where Active Directory (AD), or a similar technology, may be used to centrally manage identities and permissions, but asset/process owners are authorized to operate a decentralized access control program for their specific systems, applications and services. • IAM controls are primarily administrative in nature (e.g., policies & standards) to manage accounts and permissions. • IT personnel identify and implement IAM cybersecurity & data protection controls that are appropriate to address applicable statutory, regulatory and contractual requirements. | U5: Identification & Authentication (IAC) efforts are requirements-driven and governed at a local/regional level, but are not consistent across the organization. CMM Level 2 control maturity would reasonably expect all, or at least most, the following criteria to exist: • Logical Access Control (LAC) is decentralized (e.g., a localized/regionalized function) and uses non-standardized methods to implement secure, resilient and compliant practices. • IT/cybersecurity personnel identify cybersecurity & data protection controls that are appropriate to address applicable statutory, regulatory and contractual requirements for logical access control. • IT personnel: o Implement and maintain an Identity & Access Management (IAM) capability for all users to implement “least privileges” Role Based Access Control (RBAC) practices for the management of user, group and system accounts, including privileged accounts. o Govern IAM technologies via RBAC to prohibit privileged access by non-organizational users, unless there is an explicit support contract for privileged IT support services. • Active Directory (AD), or a similar technology, is primarily used to centrally manage identities and permissions with RBAC. Due to technical or business limitations, asset/process owners are empowered to operate a decentralized access control program for their specific systems, applications and services that cannot be integrated into AD. • IAM controls are primarily administrative in nature (e.g., policies & standards) to manage accounts and permissions. • Administrative processes and technologies review all system accounts and disable any account that cannot be associated with a business process and owner. | V5: Identification & Authentication (IAC) efforts are standardized across the organization and centrally managed, where technically feasible, to ensure consistency. CMM Level 3 control maturity would reasonably expect all, or at least most, the following criteria to exist: • An Identity & Access Management (IAM) function, or similar function, centrally manages permissions and implements “least privileges” Role Based Access Control (RBAC) practices for the management of user, group and system accounts, including privileged accounts. • The Human Resources (HR) department governs personnel management operations and notifies IAM personnel of personnel role changes for RBAC-based provisioning and deprovisioning actions. • An IT Asset Management (ITAM) function, or similar function, categorizes endpoint devices according to the data the asset stores, transmits and/ or processes and applies the appropriate technology controls to protect the asset and data that conform to industry-recognized standards for hardening (e.g., DISA STIGs, CIS Benchmarks or OEM security guides). • An IT infrastructure team, or similar function, ensures that statutory, regulatory and contractual cybersecurity & data privacy obligations are addressed to ensure secure configurations are designed, built and maintained. • Active Directory (AD), or a similar technology, is used to centrally manage identities and permissions. Only by exception due to a technical or business limitation are solutions authorized to operate a decentralized access control program for systems, applications and services. • Administrative processes and technologies review all system accounts and disable any account that cannot be associated with a business process and owner. | W5: Identification & Authentication (IAC) efforts are metrics driven and provide sufficient management insight (based on a quantitative understanding of process capabilities) to predict optimal performance, ensure continued operations and identify areas for improvement. In addition to CMM Level 3 criteria, CMM Level 4 control maturity would reasonably expect all, or at least most, the following criteria to exist: • Metrics reporting includes quantitative analysis of Key Performance Indicators (KPIs). • Metrics reporting includes quantitative analysis of Key Risk Indicators (KRIs). • Scope of metrics, KPIs and KRIs covers organization-wide cybersecurity & data protection controls, including functions performed by third-parties. • Organizational leadership maintains a formal process to objectively review and respond to metrics, KPIs and KRIs (e.g., monthly or quarterly review). • Based on metrics analysis, process improvement recommendations are submitted for review and are handled in accordance with change control processes. • Both business and technical stakeholders are involved in reviewing and approving proposed changes. | X5: See C|P-CMM4. There are no defined C|P-CMM5 criteria, since it is reasonable to assume a continuously-improving process is not necessary to periodically-review the privileges assigned to individuals and service accounts to validate the need for such privileges and reassign or remove unnecessary privileges, as necessary. | AA5: 7.2.4 7.2.5.1 | AC5: R-AC-1 R-AC-2 R-AC-3 R-AC-4 R-AM-1 R-AM-2 R-AM-3 R-BC-1 R-BC-2 R-BC-3 R-BC-4 R-EX-1 R-EX-2 R-EX-3 R-EX-4 R-EX-5 R-EX-6 R-EX-7 R-GV-1 R-GV-2 R-GV-3 R-GV-4 R-GV-5 R-GV-6 R-GV-7 R-GV-8 R-IR-1 R-IR-2 R-IR-3 R-IR-4 R-SA-1 R-SC-1 R-SC-2 R-SC-3 R-SC-4 R-SC-5 R-SC-6 | AD5: R-AC-1 | AE5: R-AC-2 | AF5: R-AC-3 | AG5: R-AC-4 | AH5: R-AM-1 | AI5: R-AM-2 | AJ5: R-AM-3 | AK5: R-BC-1 | AL5: R-BC-2 | AM5: R-BC-3 | AN5: R-BC-4 | AP5: R-EX-1 | AQ5: R-EX-2 | AR5: R-EX-3 | AS5: R-EX-4 | AT5: R-EX-5 | AU5: R-EX-6 | AV5: R-EX-7 | AW5: R-GV-1 | AX5: R-GV-2 | AY5: R-GV-3 | AZ5: R-GV-4 | BA5: R-GV-5 | BB5: R-GV-6 | BC5: R-GV-7 | BD5: R-GV-8 | BE5: R-IR-1 | BF5: R-IR-2 | BG5: R-IR-3 | BH5: R-IR-4 | BI5: R-SA-1 | BK5: R-SC-1 | BL5: R-SC-2 | BM5: R-SC-3 | BN5: R-SC-4 | BO5: R-SC-5 | BP5: R-SC-6 | BQ5: =_xlfn.TEXTJOIN(CHAR(10),TRUE,BR5:DB5) -> NT-7 MT-1 MT-2 MT-7 MT-8 MT-9 MT-10 MT-11 MT-12 MT-13 MT-14 MT-15 | BX5: NT-7 | CF5: MT-1 | CG5: MT-2 | CL5: MT-7 | CM5: MT-8 | CN5: MT-9 | CO5: MT-10 | CP5: MT-11 | CQ5: MT-12 | CR5: MT-13 | CS5: MT-14 | CT5: MT-15
A6: Network Security | B6: Host Containment | C6: =VLOOKUP(D6,'Threat Model'!$P$2:$Q$96,1,FALSE) -> #N/A | D6: NET-08.3 | E6: Automated mechanisms exist to enforce host containment protections that revoke or quarantine a host’s access to the network. | H6: Does the organization use automated mechanisms to enforce host containment protections that revoke or quarantine a host’s access to the network? | I6: 3 | L6: x | O6: Protect | R6: x | S6: There is no evidence of an automated capability to enforce host containment protections that revoke or quarantine a host’s access to the network. | T6: C|P-CMM1 is N/A, since a structured process is required to enforce host containment protections that revoke or quarantine a host’s access to the network. | U6: C|P-CMM2 is N/A, since a well-defined process is required to enforce host containment protections that revoke or quarantine a host’s access to the network. | V6: Network Security (NET) efforts are standardized across the organization and centrally managed, where technically feasible, to ensure consistency. CMM Level 3 control maturity would reasonably expect all, or at least most, the following criteria to exist: • A Technology Infrastructure team, or similar function, defines centrally-managed network security controls for implementation across the enterprise. • Secure engineering principles are used to design and implement network security controls (e.g., industry-recognized secure practices) to enforce the concepts of least privilege and least functionality at the network level. • IT/cybersecurity architects work with the Technology Infrastructure team to implement a “layered defense” network architecture that provides a defense-in-depth approach for redundancy and risk reduction for network-based security controls, including wired and wireless networking. • Administrative processes and technologies configure boundary devices (e.g., firewalls, routers, etc.) to deny network traffic by default and allow network traffic by exception (e.g., deny all, permit by exception). • Technologies automate the Access Control Lists (ACLs) and similar rulesets review process to identify security issues and/ or misconfigurations. • Network segmentation exists to implement separate network addresses (e.g., different subnets) to connect systems in different security domains (e.g., sensitive/regulated data environments). | W6: See C|P-CMM3. There are no defined C|P-CMM4 criteria, since it is reasonable to assume a quantitatively-controlled process is not necessary to enforce host containment protections that revoke or quarantine a host’s access to the network. | X6: See C|P-CMM4. There are no defined C|P-CMM5 criteria, since it is reasonable to assume a continuously-improving process is not necessary to enforce host containment protections that revoke or quarantine a host’s access to the network. | Y6: 1.2 | AC6: R-AC-1 R-AC-2 R-AC-3 R-AC-4 R-AM-1 R-AM-2 R-AM-3 R-BC-1 R-BC-2 R-BC-3 R-BC-4 R-BC-5 R-EX-1 R-EX-2 R-EX-3 R-EX-4 R-EX-5 R-EX-6 R-EX-7 R-GV-1 R-GV-2 R-GV-3 R-GV-4 R-GV-5 R-GV-6 R-GV-7 R-GV-8 R-IR-1 R-IR-2 R-IR-3 R-IR-4 R-SA-1 R-SC-1 R-SC-2 R-SC-3 R-SC-4 R-SC-5 R-SC-6 | AD6: R-AC-1 | AE6: R-AC-2 | AF6: R-AC-3 | AG6: R-AC-4 | AH6: R-AM-1 | AI6: R-AM-2 | AJ6: R-AM-3 | AK6: R-BC-1 | AL6: R-BC-2 | AM6: R-BC-3 | AN6: R-BC-4 | AO6: R-BC-5 | AP6: R-EX-1 | AQ6: R-EX-2 | AR6: R-EX-3 | AS6: R-EX-4 | AT6: R-EX-5 | AU6: R-EX-6 | AV6: R-EX-7 | AW6: R-GV-1 | AX6: R-GV-2 | AY6: R-GV-3 | AZ6: R-GV-4 | BA6: R-GV-5 | BB6: R-GV-6 | BC6: R-GV-7 | BD6: R-GV-8 | BE6: R-IR-1 | BF6: R-IR-2 | BG6: R-IR-3 | BH6: R-IR-4 | BI6: R-SA-1 | BK6: R-SC-1 | BL6: R-SC-2 | BM6: R-SC-3 | BN6: R-SC-4 | BO6: R-SC-5 | BP6: R-SC-6 | BQ6: =_xlfn.TEXTJOIN(CHAR(10),TRUE,BR6:DB6) -> MT-2 MT-7 MT-8 MT-9 MT-10 MT-11 MT-12 MT-13 MT-14 MT-15 | CG6: MT-2 | CL6: MT-7 | CM6: MT-8 | CN6: MT-9 | CO6: MT-10 | CP6: MT-11 | CQ6: MT-12 | CR6: MT-13 | CS6: MT-14 | CT6: MT-15 | EA6: Row Labels | EB6: Count of Relative Control Weighting | EC6: Sum of Relative Control Weighting
A7: Asset Management | B7: Component Duplication Avoidance | C7: =VLOOKUP(D7,'Threat Model'!$P$2:$Q$96,1,FALSE) -> #N/A | D7: AST-02.3 | E7: Mechanisms exist to establish and maintain an authoritative source and repository to provide a trusted source and accountability for approved and implemented system components that prevents assets from being duplicated in other asset inventories. | G7: ∙ Configuration Management Database (CMDB) | H7: Does the organization establish and maintain an authoritative source and repository to provide a trusted source and accountability for approved and implemented system components that prevents assets from being duplicated in other asset inventories? | I7: 2 | K7: x | O7: Identify | Q7: x | R7: x | S7: There is no evidence of a capability to establish and maintain an authoritative source and repository to provide a trusted source and accountability for approved and implemented system components that prevents assets from being duplicated in other asset inventories. | T7: C|P-CMM1 is N/A, since a structured process is required to establish and maintain an authoritative source and repository to provide a trusted source and accountability for approved and implemented system components that prevents assets from being duplicated in other asset inventories. | U7: C|P-CMM2 is N/A, since a well-defined process is required to establish and maintain an authoritative source and repository to provide a trusted source and accountability for approved and implemented system components that prevents assets from being duplicated in other asset inventories. | V7: Asset Management (AST) efforts are standardized across the organization and centrally managed, where technically feasible, to ensure consistency. CMM Level 3 control maturity would reasonably expect all, or at least most, the following criteria to exist: • An IT Asset Management (ITAM) function, or similar function, governs asset management to help ensure compliance with requirements for asset management. • An ITAM function, or similar function, maintains an inventory of IT assets, covering both physical and virtual assets, as well as centrally managed asset ownership assignments. • Technology assets and data are categorized according to data classification and business criticality criteria. • A Cybersecurity Supply Chain Risk Management (C-SCRM) function oversees supply chain risks including the removal and prevention of certain technology services and/ or equipment designated as supply chain threats by a statutory or regulatory body. • Data/process owners document where sensitive/regulated data is stored, transmitted and processed, generating Data Flow Diagrams (DFDs) and network diagrams to document the flow of data. | W7: Asset Management (AST) efforts are metrics driven and provide sufficient management insight (based on a quantitative understanding of process capabilities) to predict optimal performance, ensure continued operations and identify areas for improvement. • Metrics reporting includes quantitative analysis of Key Performance Indicators (KPIs). • Metrics reporting includes quantitative analysis of Key Risk Indicators (KRIs). • Scope of metrics, KPIs and KRIs covers organization-wide cybersecurity & data protection controls, including functions performed by third-parties. • Organizational leadership maintains a formal process to objectively review and respond to metrics, KPIs and KRIs (e.g., monthly or quarterly review). • Based on metrics analysis, process improvement recommendations are submitted for review and are handled in accordance with change control processes. • Both business and technical stakeholders are involved in reviewing and approving proposed changes. | X7: See C|P-CMM4. There are no defined C|P-CMM5 criteria, since it is reasonable to assume a continuously-improving process is not necessary to establish and maintain an authoritative source and repository to provide a trusted source and accountability for approved and implemented system components that prevents assets from being duplicated in other asset inventories. | Y7: 1.3 | AC7: R-AM-3 R-BC-2 R-EX-1 R-EX-2 R-EX-3 R-EX-4 R-EX-5 R-EX-6 R-GV-6 R-GV-7 R-SC-1 R-SC-2 R-SC-3 R-SC-4 R-SC-5 R-SC-6 | AJ7: R-AM-3 | AL7: R-BC-2 | AP7: R-EX-1 | AQ7: R-EX-2 | AR7: R-EX-3 | AS7: R-EX-4 | AT7: R-EX-5 | AU7: R-EX-6 | BB7: R-GV-6 | BC7: R-GV-7 | BK7: R-SC-1 | BL7: R-SC-2 | BM7: R-SC-3 | BN7: R-SC-4 | BO7: R-SC-5 | BP7: R-SC-6 | BQ7: =_xlfn.TEXTJOIN(CHAR(10),TRUE,BR7:DB7) -> NT-7 MT-1 MT-2 MT-7 MT-8 MT-9 MT-10 MT-11 MT-12 MT-13 MT-14 MT-15 | BX7: NT-7 | CF7: MT-1 | CG7: MT-2 | CL7: MT-7 | CM7: MT-8 | CN7: MT-9 | CO7: MT-10 | CP7: MT-11 | CQ7: MT-12 | CR7: MT-13 | CS7: MT-14 | CT7: MT-15 | EA7: 1 | EB7: 2 | EC7: 0.00045279602
A8: Asset Management | B8: Software Licensing Restrictions | C8: =VLOOKUP(D8,'Threat Model'!$P$2:$Q$96,1,FALSE) -> #N/A | D8: AST-02.7 | E8: Mechanisms exist to protect Intellectual Property (IP) rights with software licensing restrictions. | G8: ∙ IT Asset Management (ITAM) program | H8: Does the organization protect Intellectual Property (IP) rights with software licensing restrictions? | I8: 8 | L8: x | O8: Identify | R8: x | S8: There is no evidence of a capability to protect Intellectual Property (IP) rights with software licensing restrictions. | T8: Asset Management (AST) efforts are ad hoc and inconsistent. CMM Level 1 control maturity would reasonably expect all, or at least most, the following criteria to exist: • Asset management is informally assigned as an additional duty to existing IT/cybersecurity personnel. • Asset inventories are performed in an ad hoc manner. • Software licensing is tracked as part of IT asset inventories. • Data process owners maintain limited network diagrams to document the flow of sensitive/regulated data that is specific to their initiative. • IT personnel work with data/process owners to help ensure secure practices are implemented throughout the System Development Lifecycle (SDLC) for all high-value projects. | U8: Asset Management (AST) efforts are requirements-driven and governed at a local/regional level, but are not consistent across the organization. CMM Level 2 control maturity would reasonably expect all, or at least most, the following criteria to exist: • Asset management is decentralized (e.g., a localized/regionalized function) and uses non-standardized methods to implement secure, resilient and compliant practices. • IT/cybersecurity personnel identify cybersecurity & data protection controls that are appropriate to address applicable statutory, regulatory and contractual requirements for asset management. • Administrative processes and technologies focus on protecting High Value Assets (HVAs), including environments where sensitive/regulated data is stored, transmitted and processed. • Asset management is formally assigned as an additional duty to existing IT/cybersecurity personnel. • Technology assets are categorized according to data classification and business criticality. • Inventories cover technology assets in scope for statutory, regulatory and/ or contractual compliance, which includes both physical and virtual assets. • Software licensing is tracked as part of IT asset inventories. • Users are educated on their responsibilities to protect technology assets assigned to them or under their supervision. • IT/cybersecurity personnel maintain network diagrams to document the flow of sensitive/regulated data across the network. • Organizational policies and standards cover software licensing restrictions for users, as part of acceptable and unacceptable behaviors. | V8: Asset Management (AST) efforts are standardized across the organization and centrally managed, where technically feasible, to ensure consistency. CMM Level 3 control maturity would reasonably expect all, or at least most, the following criteria to exist: • An IT Asset Management (ITAM) function, or similar function, governs asset management to help ensure compliance with requirements for asset management. • An ITAM function, or similar function, maintains an inventory of IT assets, covering both physical and virtual assets, as well as centrally managed asset ownership assignments. • Technology assets and data are categorized according to data classification and business criticality criteria. • A Cybersecurity Supply Chain Risk Management (C-SCRM) function oversees supply chain risks including the removal and prevention of certain technology services and/ or equipment designated as supply chain threats by a statutory or regulatory body. • Data/process owners document where sensitive/regulated data is stored, transmitted and processed, generating Data Flow Diagrams (DFDs) and network diagrams to document the flow of data. • Organizational policies and standards cover software licensing restrictions for users, as part of acceptable and unacceptable behaviors. • Software license violations are investigated by the ITAM team, in coordination with cybersecurity personnel, whenever necessary. | W8: Asset Management (AST) efforts are metrics driven and provide sufficient management insight (based on a quantitative understanding of process capabilities) to predict optimal performance, ensure continued operations and identify areas for improvement. • Metrics reporting includes quantitative analysis of Key Performance Indicators (KPIs). • Metrics reporting includes quantitative analysis of Key Risk Indicators (KRIs). • Scope of metrics, KPIs and KRIs covers organization-wide cybersecurity & data protection controls, including functions performed by third-parties. • Organizational leadership maintains a formal process to objectively review and respond to metrics, KPIs and KRIs (e.g., monthly or quarterly review). • Based on metrics analysis, process improvement recommendations are submitted for review and are handled in accordance with change control processes. • Both business and technical stakeholders are involved in reviewing and approving proposed changes. | X8: See C|P-CMM4. There are no defined C|P-CMM5 criteria, since it is reasonable to assume a continuously-improving process is not necessary to protect Intellectual Property (IP) rights with software licensing restrictions. | Y8: 2.2 | AC8: R-AC-3 R-AM-1 R-AM-3 R-BC-4 R-EX-1 R-EX-2 R-EX-3 R-EX-4 R-EX-5 R-EX-6 R-EX-7 R-GV-1 R-GV-2 R-GV-4 R-GV-6 R-IR-3 R-SA-1 | AF8: R-AC-3 | AH8: R-AM-1 | AJ8: R-AM-3 | AN8: R-BC-4 | AP8: R-EX-1 | AQ8: R-EX-2 | AR8: R-EX-3 | AS8: R-EX-4 | AT8: R-EX-5 | AU8: R-EX-6 | AV8: R-EX-7 | AW8: R-GV-1 | AX8: R-GV-2 | AZ8: R-GV-4 | BB8: R-GV-6 | BG8: R-IR-3 | BI8: R-SA-1 | BQ8: =_xlfn.TEXTJOIN(CHAR(10),TRUE,BR8:DB8) -> NT-7 MT-1 MT-2 MT-7 MT-8 MT-9 MT-10 MT-11 MT-12 MT-13 MT-14 MT-15 | BX8: NT-7 | CF8: MT-1 | CG8: MT-2 | CL8: MT-7 | CM8: MT-8 | CN8: MT-9 | CO8: MT-10 | CP8: MT-11 | CQ8: MT-12 | CR8: MT-13 | CS8: MT-14 | CT8: MT-15 | EA8: 2 | EB8: 2 | EC8: 0.00090559203
A9: Risk Management | B9: Compensating Countermeasures | C9: =VLOOKUP(D9,'Threat Model'!$P$2:$Q$96,1,FALSE) -> #N/A | D9: RSK-06.2 | E9: Mechanisms exist to identify and implement compensating countermeasures to reduce risk and exposure to threats. | F9: E-RSK-03 | G9: ∙ Risk Management Program (RMP) | H9: Does the organization identify and implement compensating countermeasures to reduce risk and exposure to threats? | I9: 9 | K9: x | O9: Respond | Q9: x | S9: There is no evidence of a capability to identify and implement compensating countermeasures to reduce risk and exposure to threats. | T9: C|P-CMM1 is N/A, since a structured process is required to identify and implement compensating countermeasures to reduce risk and exposure to threats. | U9: Risk Management efforts are requirements-driven and governed at a local/regional level, but are not consistent across the organization. CMM Level 2 control maturity would reasonably expect all, or at least most, the following criteria to exist: • Risk management is decentralized (e.g., a localized/regionalized function) and uses non-standardized methods to implement secure, resilient and compliant practices. • Data/process owners are expected to self-manage risks associated with their systems, applications, services and data, based on the organization's published policies and standards, including the identification, remediation and reporting of risks. • Data/process owners work with IT/cybersecurity personnel and Data Protection Officers (DPOs) to ensure applicable statutory, regulatory and contractual obligations are properly addressed, including the storage, transmission and processing of sensitive/regulated data. • IT/cybersecurity personnel: o Identify cybersecurity & data protection controls to address applicable statutory, regulatory and contractual requirements for risk management. o Implement and maintain a form of Risk Management Program (RMP) that provides operational guidance on how risk is identified, assessed, remediated and reported. • Risk management processes (e.g., risk assessments) and technologies focus on protecting High Value Assets (HVAs), including environments where sensitive/regulated data is stored, transmitted and processed. | V9: Risk Management efforts are standardized across the organization and centrally managed, where technically feasible, to ensure consistency. CMM Level 3 control maturity would reasonably expect all, or at least most, the following criteria to exist: • A formal Risk Management Program (RMP) provides enterprise-wide guidance on how risk is to be identified, framed (e.g., risk appetite, risk tolerance, risk thresholds, etc.) assessed, mitigated/remediated and reported. • Criteria to define materiality for risk management decisions is defined. • A steering committee is formally established to provide executive oversight of the cybersecurity & data privacy program, including appropriately resourcing risk management operations. • A formally-documented Cybersecurity Supply Chain Risk Management (C-SCRM) plan exists to identify, assess and mitigate supply chain-related risks and threats; • The Chief Information Security Officer (CISO), or similar function with technical competence to address cybersecurity concerns, o Analyzes the organization's business strategy to determine prioritized and authoritative guidance for Risk Management (RM) practices. o Develops a security-focused Concept of Operations (CONOPS) that documents management, operational and technical measures to apply defense-in-depth techniques across the enterprise for RM. • A Governance, Risk & Compliance (GRC) function, or similar function: o Provides governance oversight for the implementation of applicable statutory, regulatory and contractual cybersecurity & data protection controls to protect the confidentiality, integrity, availability and safety of the organization's applications, systems, services and data with regards to RM. o Maintains a common taxonomy of risk-relevant terminology to minimize assumptions and misunderstandings. o Enables data/process owners to conduct annual risk assessment of their operations that includes the likelihood and magnitude of harm, from unauthorized access, use, disclosure, disruption, modification or destruction of the organization's systems and data. o Assists users in making informed risk decisions to ensure data and processes are appropriately protected. o Enables the documentation of risk assessments, risk response and risk monitoring to support statutory, regulatory and contractual obligations for risk management practices. o Maintains a centralized risk register to reflect an active recording and disposition of identified risks. The risk register identifies and assigns a risk ranking to vulnerabilities and risks that is based on industry-recognized practices and facilitates monitoring and reporting of those risks. o Governs supply chain risks associated with the development, acquisition, maintenance and disposal of systems, system components and services. • An IT Asset Management (ITAM) function, or similar function, categorizes assets according to the data the asset stores, transmits and/ or processes, applying the appropriate technology controls to protect the asset and data. | W9: See C|P-CMM3. There are no defined C|P-CMM4 criteria, since it is reasonable to assume a quantitatively-controlled process is not necessary to identify and implement compensating countermeasures to reduce risk and exposure to threats. | X9: See C|P-CMM4. There are no defined C|P-CMM5 criteria, since it is reasonable to assume a continuously-improving process is not necessary to identify and implement compensating countermeasures to reduce risk and exposure to threats. | Y9: 2.2 | Z9: GV.RM-04 ID.RA-06 | AA9: 1.2.6 2.2.4 12.3.1 12.3.2 | AC9: R-AC-1 R-AC-2 R-AC-3 R-AC-4 R-AM-1 R-AM-2 R-BC-1 R-BC-2 R-BC-3 R-BC-4 R-BC-5 R-EX-1 R-EX-2 R-EX-3 R-EX-4 R-EX-5 R-EX-6 R-EX-7 R-GV-1 R-GV-2 R-GV-3 R-GV-4 R-GV-5 R-GV-6 R-GV-7 R-GV-8 R-IR-1 R-IR-2 R-IR-3 R-IR-4 R-SA-1 R-SA-2 R-SC-1 R-SC-2 R-SC-3 R-SC-4 R-SC-5 R-SC-6 | AD9: R-AC-1 | AE9: R-AC-2 | AF9: R-AC-3 | AG9: R-AC-4 | AH9: R-AM-1 | AI9: R-AM-2 | AK9: R-BC-1 | AL9: R-BC-2 | AM9: R-BC-3 | AN9: R-BC-4 | AO9: R-BC-5 | AP9: R-EX-1 | AQ9: R-EX-2 | AR9: R-EX-3 | AS9: R-EX-4 | AT9: R-EX-5 | AU9: R-EX-6 | AV9: R-EX-7 | AW9: R-GV-1 | AX9: R-GV-2 | AY9: R-GV-3 | AZ9: R-GV-4 | BA9: R-GV-5 | BB9: R-GV-6 | BC9: R-GV-7 | BD9: R-GV-8 | BE9: R-IR-1 | BF9: R-IR-2 | BG9: R-IR-3 | BH9: R-IR-4 | BI9: R-SA-1 | BJ9: R-SA-2 | BK9: R-SC-1 | BL9: R-SC-2 | BM9: R-SC-3 | BN9: R-SC-4 | BO9: R-SC-5 | BP9: R-SC-6 | BQ9: =_xlfn.TEXTJOIN(CHAR(10),TRUE,BR9:DB9) -> NT-1 NT-2 NT-3 NT-4 NT-5 NT-6 NT-7 NT-8 NT-9 NT-10 NT-11 NT-12 NT-13 NT-14 MT-1 MT-2 MT-3 MT-4 MT-5 MT-6 MT-7 MT-8 MT-9 MT-11 MT-12 MT-13 MT-14 MT-15 | BR9: NT-1 | BS9: NT-2 | BT9: NT-3 | BU9: NT-4 | BV9: NT-5 | BW9: NT-6 | BX9: NT-7 | BY9: NT-8 | BZ9: NT-9 | CA9: NT-10 | CB9: NT-11 | CC9: NT-12 | CD9: NT-13 | CE9: NT-14 | CF9: MT-1 | CG9: MT-2 | CH9: MT-3 | CI9: MT-4 | CJ9: MT-5 | CK9: MT-6 | CL9: MT-7 | CM9: MT-8 | CN9: MT-9 | CP9: MT-11 | CQ9: MT-12 | CR9: MT-13 | CS9: MT-14 | CT9: MT-15 | EA9: 3 | EB9: 12 | EC9: 0.0081503283
